Workbook

Sheet Summary
A1: Zefanya Mobile App - Combined Test Results
A2: Static code review of lib.zip (mock-data build). Not run on a device. Blocked = needs phone, live API or seeded data. Edit Status on the All Results sheet and these counts update.
A4: Workbook | B4: Total | C4: Pass | D4: Fail | E4: Blocked | F4: Not Run | G4: Pass rate
A5: Buyer - Account Creation | B5: =COUNTIF('All Results'!$A$2:$A$378,A5) -> 42 | C5: =COUNTIFS('All Results'!$A$2:$A$378,$A5,'All Results'!$H$2:$H$378,"Pass") -> 18 | D5: =COUNTIFS('All Results'!$A$2:$A$378,$A5,'All Results'!$H$2:$H$378,"Fail") -> 9 | E5: =COUNTIFS('All Results'!$A$2:$A$378,$A5,'All Results'!$H$2:$H$378,"Blocked") -> 15 | F5: =B5-C5-D5-E5 -> 0 | G5: =IF(B5=0,0,C5/B5) -> 0.42857143
A6: Courier - Account Creation | B6: =COUNTIF('All Results'!$A$2:$A$378,A6) -> 52 | C6: =COUNTIFS('All Results'!$A$2:$A$378,$A6,'All Results'!$H$2:$H$378,"Pass") -> 2 | D6: =COUNTIFS('All Results'!$A$2:$A$378,$A6,'All Results'!$H$2:$H$378,"Fail") -> 9 | E6: =COUNTIFS('All Results'!$A$2:$A$378,$A6,'All Results'!$H$2:$H$378,"Blocked") -> 41 | F6: =B6-C6-D6-E6 -> 0 | G6: =IF(B6=0,0,C6/B6) -> 0.038461538
A7: Rider - Account Creation | B7: =COUNTIF('All Results'!$A$2:$A$378,A7) -> 47 | C7: =COUNTIFS('All Results'!$A$2:$A$378,$A7,'All Results'!$H$2:$H$378,"Pass") -> 1 | D7: =COUNTIFS('All Results'!$A$2:$A$378,$A7,'All Results'!$H$2:$H$378,"Fail") -> 8 | E7: =COUNTIFS('All Results'!$A$2:$A$378,$A7,'All Results'!$H$2:$H$378,"Blocked") -> 38 | F7: =B7-C7-D7-E7 -> 0 | G7: =IF(B7=0,0,C7/B7) -> 0.021276596
A8: Buyer - Modules | B8: =COUNTIF('All Results'!$A$2:$A$378,A8) -> 131 | C8: =COUNTIFS('All Results'!$A$2:$A$378,$A8,'All Results'!$H$2:$H$378,"Pass") -> 21 | D8: =COUNTIFS('All Results'!$A$2:$A$378,$A8,'All Results'!$H$2:$H$378,"Fail") -> 85 | E8: =COUNTIFS('All Results'!$A$2:$A$378,$A8,'All Results'!$H$2:$H$378,"Blocked") -> 25 | F8: =B8-C8-D8-E8 -> 0 | G8: =IF(B8=0,0,C8/B8) -> 0.16030534
A9: Courier - Modules | B9: =COUNTIF('All Results'!$A$2:$A$378,A9) -> 52 | C9: =COUNTIFS('All Results'!$A$2:$A$378,$A9,'All Results'!$H$2:$H$378,"Pass") -> 0 | D9: =COUNTIFS('All Results'!$A$2:$A$378,$A9,'All Results'!$H$2:$H$378,"Fail") -> 46 | E9: =COUNTIFS('All Results'!$A$2:$A$378,$A9,'All Results'!$H$2:$H$378,"Blocked") -> 6 | F9: =B9-C9-D9-E9 -> 0 | G9: =IF(B9=0,0,C9/B9) -> 0
A10: Rider - Modules | B10: =COUNTIF('All Results'!$A$2:$A$378,A10) -> 53 | C10: =COUNTIFS('All Results'!$A$2:$A$378,$A10,'All Results'!$H$2:$H$378,"Pass") -> 2 | D10: =COUNTIFS('All Results'!$A$2:$A$378,$A10,'All Results'!$H$2:$H$378,"Fail") -> 39 | E10: =COUNTIFS('All Results'!$A$2:$A$378,$A10,'All Results'!$H$2:$H$378,"Blocked") -> 12 | F10: =B10-C10-D10-E10 -> 0 | G10: =IF(B10=0,0,C10/B10) -> 0.037735849
A11: Total | B11: =SUM(B5:B10) -> 377 | C11: =SUM(C5:C10) -> 44 | D11: =SUM(D5:D10) -> 196 | E11: =SUM(E5:E10) -> 137 | F11: =SUM(F5:F10) -> 0 | G11: =IF(B11=0,0,C11/B11) -> 0.11671088

Sheet All Results
A1: Workbook | B1: Sheet | C1: Module | D1: Test Case ID | E1: Test Scenario | F1: Expected Result | G1: Actual Result | H1: Status | I1: Remarks
A2: Buyer - Account Creation | B2: Buyer | C2: Registration Form | D2: TC-BUY-001 | E2: Register with all valid data | F2: The form is accepted with no validation errors. A success message is shown, a 6-digit OTP is sent to the email, and the email verification screen opens. The account is saved with status Unverified. | G2: Mock build: Submit goes straight to the Under Review screen and no OTP is sent. The form also asks for Sex, Middle Initial, address and a Gov ID upload that are not in the test data. | H2: Blocked | I2: Needs live Laravel API (--dart-define=zefanya.useLiveApi=true). Check OTP email and Unverified status there.
A3: Buyer - Account Creation | B3: Buyer | C3: Required Fields | D3: TC-BUY-002 | E3: Submit a completely empty form | F3: Registration is blocked. A required-field message is shown for every mandatory field. No account is created and no OTP is sent. | G3: Continue on step 1 flags every empty required field (names, sex, email, phone, date of birth). Nothing is submitted. | H3: Pass | I3: Wizard validates per step; password, address and ID are flagged when their step is reached.
A4: Buyer - Account Creation | B4: Buyer | C4: Required Fields | D4: TC-BUY-003 | E4: Leave one required field blank at a time | F4: Each time, registration is blocked and a required-field message is shown on the blank field only. Other entered values (except passwords and uploads) are kept. No account is created. | G4: Each required field shows its own message; other values stay in the form. | H4: Pass
A5: Buyer - Account Creation | B5: Buyer | C5: Name | D5: TC-BUY-004 | E5: Name with numbers or symbols | F5: Registration is blocked. A message on each name field says only letters are allowed. | G5: Names with numbers and symbols are accepted. Only length of at least 2 is checked. | H5: Fail | I5: Add a letters/space/hyphen/apostrophe/period rule (A2).
A6: Buyer - Account Creation | B6: Buyer | C6: Name | D6: TC-BUY-005 | E6: Name with ñ and allowed punctuation | F6: The names are accepted and saved exactly as typed, including ñ. | G6: Names with ñ, hyphen and apostrophe are accepted and kept as typed. | H6: Pass
A7: Buyer - Account Creation | B7: Buyer | C7: Name | D7: TC-BUY-006 | E7: Name length at the limits | F7: 1 and 51 characters are rejected with a length message. 2 and 50 characters are accepted. | G7: 1 character shows "First name is required" (not a length message). 51 characters is accepted; there is no 50-character limit. | H7: Fail | I7: Add max length 50 and a length message.
A8: Buyer - Account Creation | B8: Buyer | C8: Date of Birth | D8: TC-BUY-007 | E8: Age at the 18-year limit | F8: The 17-year-old date is rejected with a message that the person must be at least 18. The other two dates are accepted. | G8: The age is calculated but never checked. A 17-year-old date of birth is accepted. | H8: Fail | I8: registration_screen.dart _pickDob: add age >= 18 validation (A6).
A9: Buyer - Account Creation | B9: Buyer | C9: Date of Birth | D9: TC-BUY-008 | E9: Date of birth in the future | F9: Registration is blocked. A message asks for a valid date of birth. If a date picker is used, future dates cannot be selected. | G9: The date picker stops at today, so a future date cannot be chosen. | H9: Pass
A10: Buyer - Account Creation | B10: Buyer | C10: Email | D10: TC-BUY-009 | E10: Email in an invalid format | F10: Each value is rejected with a message asking for a valid email address. No account is created. | G10: All five values are rejected with "Enter a valid email address". | H10: Pass
A11: Buyer - Account Creation | B11: Buyer | C11: Email | D11: TC-BUY-010 | E11: Email that is already registered | F11: Registration is blocked. A message says the email is already in use. No account is created. | G11: Mock repository has no account store, so a duplicate email is never detected. | H11: Blocked | I11: Needs live Laravel API (--dart-define=zefanya.useLiveApi=true).
A12: Buyer - Account Creation | B12: Buyer | C12: Email | D12: TC-BUY-011 | E12: Registered email typed in capital letters | F12: The email is treated as a duplicate. Registration is blocked. | G12: Duplicate detection (case-insensitive) is a server rule; the mock does not do it. | H12: Blocked | I12: Needs live Laravel API (--dart-define=zefanya.useLiveApi=true).
A13: Buyer - Account Creation | B13: Buyer | C13: Email | D13: TC-BUY-012 | E13: Email with spaces before and after | F13: The spaces are removed and the email is saved as buyer.test01@example.com. | G13: Spaces are trimmed before validating and before submitting. | H13: Pass
A14: Buyer - Account Creation | B14: Buyer | C14: Mobile Number | D14: TC-BUY-013 | E14: Mobile number in an invalid format | F14: Each value is rejected with a message asking for a valid mobile number. | G14: All four values are rejected with "Enter a valid PH number (09XXXXXXXXX)". | H14: Pass
A15: Buyer - Account Creation | B15: Buyer | C15: Mobile Number | D15: TC-BUY-014 | E15: Mobile number length at the limits | F15: 10 and 12 digits are rejected with a length message. 11 digits is accepted. | G15: 10 and 12 digits are rejected; 11 digits is accepted. | H15: Pass | I15: The message is a format message, not a length message.
A16: Buyer - Account Creation | B16: Buyer | C16: Mobile Number | D16: TC-BUY-015 | E16: Mobile number that is already registered | F16: Registration is blocked. A message says the mobile number is already in use. | G16: Duplicate mobile numbers are only detectable by the server. | H16: Blocked | I16: Needs live Laravel API (--dart-define=zefanya.useLiveApi=true).
A17: Buyer - Account Creation | B17: Buyer | C17: Mobile Number | D17: TC-BUY-016 | E17: Registered number entered in +63 format | F17: The +63 format is recognised as the same number. Registration is blocked. A message says the mobile number is already in use. | G17: +63 and 09 forms both pass the format check; treating them as the same number is a server rule. | H17: Blocked | I17: Needs live Laravel API (--dart-define=zefanya.useLiveApi=true).
A18: Buyer - Account Creation | B18: Buyer | C18: Password | D18: TC-BUY-017 | E18: Password length at the limit | F18: 7 characters is rejected with a minimum-length message. 8 characters is accepted. | G18: 7 characters is rejected with "Use at least 8 characters"; 8 is accepted. | H18: Pass
A19: Buyer - Account Creation | B19: Buyer | C19: Password | D19: TC-BUY-018 | E19: Password missing a required character type | F19: Each password is rejected with a message stating the password rule. No account is created. | G19: All four passwords are accepted. Only the 8-character minimum is enforced; no upper/lower/number/special rule. | H19: Fail | I19: Add the A5 rule, or change A5 to match the server.
A20: Buyer - Account Creation | B20: Buyer | C20: Password | D20: TC-BUY-019 | E20: Confirm Password does not match | F20: Registration is blocked. A message says the passwords do not match. | G20: Shows "Passwords don't match". | H20: Pass
A21: Buyer - Account Creation | B21: Buyer | C21: Password | D21: TC-BUY-020 | E21: Password is hidden while typing | F21: Characters are hidden as dots by default. The icon reveals the password, then hides it again. | G21: Password and confirmation are obscured; the eye icon toggles each one. | H21: Pass
A22: Buyer - Account Creation | B22: Buyer | C22: Terms and Privacy Policy | D22: TC-BUY-021 | E22: Register without accepting the terms | F22: Registration is blocked. A message says the Terms and Privacy Policy must be accepted. | G22: No Terms and Privacy checkbox on the registration form. The only terms checkbox is at checkout. | H22: Fail
A23: Buyer - Account Creation | B23: Buyer | C23: Registration Form | D23: TC-BUY-022 | E23: Tap Register several times quickly | F23: Only one account is created and only one OTP email is sent. No duplicate-email error screen appears. | G23: The submit button is disabled while the request runs, so repeated taps do nothing. | H23: Pass | I23: The "only one OTP email" part needs the live API.
A24: Buyer - Account Creation | B24: Buyer | C24: Email Verification (OTP) | D24: TC-BUY-023 | E24: Verify with the correct OTP | F24: Verification succeeds. The account status changes from Unverified to Active. A success message is shown and the login screen (or home screen) opens. | G24: After the correct code (123456 in mock) the status becomes Pending Approval and the Under Review screen opens. It never becomes Active. | H24: Fail | I24: Rule conflict: A12 says buyers become Active after OTP, but the app treats them as needing admin approval. Align one of them.
A25: Buyer - Account Creation | B25: Buyer | C25: Email Verification (OTP) | D25: TC-BUY-024 | E25: Verify with an incorrect OTP | F25: Verification fails with an invalid-code message. The account stays Unverified. | G25: A wrong code is rejected with "That code doesn't match. Please try again." and the account stays unverified. | H25: Pass | I25: Mock accepts only 123456; live wording comes from the server.
A26: Buyer - Account Creation | B26: Buyer | C26: Email Verification (OTP) | D26: TC-BUY-025 | E26: OTP in the wrong format | F26: Each value is rejected. The account stays Unverified. | G26: Letters cannot be typed (digits only). 5 digits shows "The code is six digits." Blank shows a prompt. A 7th digit cannot be typed. | H26: Pass
A27: Buyer - Account Creation | B27: Buyer | C27: Email Verification (OTP) | D27: TC-BUY-026 | E27: Verify with an expired OTP | F27: Verification fails with a message that the code has expired, and a Resend option is offered. The account stays Unverified. | G27: Expiry is decided by the server. The OTP screen has no expired state or countdown. | H27: Blocked | I27: Needs live Laravel API (--dart-define=zefanya.useLiveApi=true).
A28: Buyer - Account Creation | B28: Buyer | C28: Email Verification (OTP) | D28: TC-BUY-027 | E28: Resend OTP | F28: A new OTP email arrives. The first code is rejected. The second code is accepted and the account is verified. | G28: Resend has a 30-second cooldown and shows "A new code has been sent." The mock resend sends nothing and the old code stays valid. | H28: Blocked | I28: Needs live Laravel API (--dart-define=zefanya.useLiveApi=true).
A29: Buyer - Account Creation | B29: Buyer | C29: Email Verification (OTP) | D29: TC-BUY-028 | E29: Log in before verifying the email | F29: The user is not given access. The verification screen or a message asking to verify the email is shown. | G29: Mock login accepts any email and password and opens the buyer home, even for an unverified account. | H29: Fail | I29: Live mode depends on the server answer; retest with the live API.
A30: Buyer - Account Creation | B30: Buyer | C30: Access Control | D30: TC-BUY-029 | E30: Log in with the new verified account | F30: Login succeeds. The buyer home screen opens and the name Juan Miguel is shown. | G30: Mock login accepts any credentials, so this cannot prove a real verified account works. | H30: Blocked | I30: Needs live Laravel API (--dart-define=zefanya.useLiveApi=true).
A31: Buyer - Account Creation | B31: Buyer | C31: Access Control | D31: TC-BUY-030 | E31: Open another role's screens | F31: No other role's menus are shown. Each deep link shows an access-denied message or returns to the buyer home screen. The API request is refused (401/403). No data from the other role is shown. | G31: The app has no deep links; the shell is chosen from the saved role. 401/403 handling is server-side. | H31: Blocked | I31: Needs live Laravel API (--dart-define=zefanya.useLiveApi=true). Also needs a proxy tool (M11).
A32: Buyer - Account Creation | B32: Buyer | C32: Registration Form | D32: TC-BUY-031 | E32: [Mobile] Each field opens the right keyboard | F32: Each field opens the keyboard listed in the test data. Password fields show no autocorrect or word suggestions. No field opens a keyboard that cannot type its valid value. | G32: Email uses the email keyboard, phone uses the phone keypad, names use the name keyboard, password fields are obscured. | H32: Pass | I32: Code review only; confirm on a phone.
A33: Buyer - Account Creation | B33: Buyer | C33: Registration Form | D33: TC-BUY-032 | E33: [Mobile] Keyboard never hides the active field or Register | F33: The focused field always scrolls into view above the keyboard, with its error message visible. Register can be reached and tapped. The keyboard closes when Done or the background is tapped. | G33: Cannot be judged from code. | H33: Blocked | I33: Needs a phone or emulator; code review only.
A34: Buyer - Account Creation | B34: Buyer | C34: Registration Form | D34: TC-BUY-033 | E34: [Mobile] App sent to the background while filling the form | F34: Each time, the app returns to the same form with every typed value still there (passwords may be cleared). The app does not restart, crash or jump to the login screen. No account is created until Register is tapped. | G34: Cannot be judged from code. Controllers live in the wizard state, so values should survive a pause. | H34: Blocked | I34: Needs a phone or emulator; code review only.
A35: Buyer - Account Creation | B35: Buyer | C35: Registration Form | D35: TC-BUY-034 | E35: [Mobile] Rotate the phone while the form has data | F35: Either the app stays in portrait, or the layout switches to landscape and back keeping every value and the error message. Nothing is cleared and the app does not crash. | G35: No orientation lock in code, so landscape is possible. Needs a device check. | H35: Blocked | I35: Needs a phone or emulator; code review only.
A36: Buyer - Account Creation | B36: Buyer | C36: Registration Form | D36: TC-BUY-035 | E36: [Mobile] Register with no internet connection | F36: Step 3: a clear no-internet message is shown, the typed data stays on the form, the app does not crash, and no account is created. Step 4: the account is saved once: exactly one account and one OTP email. | G36: Mock mode never touches the network. The live path shows the NetworkException message in a snackbar and keeps the form. | H36: Blocked | I36: Needs live Laravel API (--dart-define=zefanya.useLiveApi=true). Use Airplane mode.
A37: Buyer - Account Creation | B37: Buyer | C37: Registration Form | D37: TC-BUY-036 | E37: [Mobile] Connection drops right after tapping Register | F37: The app shows a connection error or a waiting state, never a frozen screen. In the end exactly one account exists with this email. If the first attempt was saved, the app continues normally (or says the account already exists and lets the user continue); the account is never left in a state the user cannot reach. | G37: Needs a real request to drop. | H37: Blocked | I37: Needs live Laravel API (--dart-define=zefanya.useLiveApi=true).
A38: Buyer - Account Creation | B38: Buyer | C38: Email Verification (OTP) | D38: TC-BUY-037 | E38: [Mobile] Paste the OTP copied from the mail app | F38: All 6 digits fill the OTP field (every box, in order, when it is split into boxes). Verification succeeds and the status changes exactly as in the correct-OTP case. | G38: The OTP field is digits-only and limited to 6, so a pasted 6-digit code fills it. | H38: Pass | I38: It is one field, not split boxes. No one-time-code autofill hint is set.
A39: Buyer - Account Creation | B39: Buyer | C39: Email Verification (OTP) | D39: TC-BUY-038 | E39: [Mobile] OTP countdown after switching to the mail app | F39: After step 2 the verification screen is still open and shows about 3 minutes left (the countdown kept running; it did not restart at 5:00). In step 3 the code is rejected as expired and Resend is offered. | G39: There is no countdown on the OTP screen, so nothing shows time left. | H39: Fail
A40: Buyer - Account Creation | B40: Buyer | C40: Email Verification (OTP) | D40: TC-BUY-039 | E40: [Mobile] System Back on the form and the verification screen | F40: Leaving a form with typed data asks first, and Cancel keeps every value. Back from the verification screen does not create a second account; the account stays Unverified, and the next login brings the user back to verification. | G40: Back on the first registration step leaves without asking. DirtyGuard is only used on Edit Profile. | H40: Fail | I40: Wrap the registration wizard in DirtyGuard (M8).
...
